Workbook

Sheet Dulieu
A1: NHCSXH CHI NHÁNH TỈNH ĐỒNG NAI
A2: PGD Định Quán
A3: CÂN ĐỐI NGUỒN VỐN VÀ SỬ DỤNG VỐN NĂM 2026
A4: (Thực hiện đến 21/04/2026)
N5: Đơn vị: triệu đồng, %
A6: TT | B6: Chỉ tiêu | C6: Mã chỉ tiêu | D6: Trong đó
D7: HST | E7: Long Thành | F7: Trảng Bom | G7: Long Khánh | H7: Xuân Lộc | I7: Định Quán | J7: Vĩnh Cửu | K7: Tân Phú | L7: Thống Nhất | M7: Cẩm Mỹ | N7: Nhơn Trạch | O7: Bình Long | P7: Lộc Ninh | Q7: Bình Phước | R7: Phước Long | S7: Bù Đăng | T7: Đồng Phú | U7: Chơn Thành | V7: Bù Đốp | W7: Bù Gia Mập | X7: Phú Riềng | Y7: Hớn Quản
A8: A | B8: NGUỒN VỐN (I+II+III) | C8: =+C26+C83 -> #VALUE! | D8: =+D26+D83 -> 726161.15 | E8: =+E26+E83 -> 578007.1 | F8: =+F26+F83 -> 622980.35 | G8: =+G26+G83 -> 754002.38 | H8: =+H26+H83 -> 735337.13 | I8: =+I26+I83 -> 606133.69 | J8: =+J26+J83 -> 644805.77 | ... Y8: =+Y26+Y83 -> 518540.26
A9: I | B9: Vốn Trung ương | C9: =+C8-C20 -> #VALUE! | D9: =+D8-D20 -> 704397.15 | E9: =+E8-E20 -> 548989.1 | F9: =+F8-F20 -> 582642.35 | G9: =+G8-G20 -> 719695.38 | H9: =+H8-H20 -> 688594.13 | I9: =+I8-I20 -> 557898.69 | J9: =+J8-J20 -> 570792.77 | ... Y9: =+Y8-Y20 -> 518440.26
A10: 1 | B10: Vốn trung ương cấp | C10: =+C9-C12 -> #VALUE! | D10: =+D9-D12 -> 489563.77 | E10: =+E9-E12 -> 469546.77 | F10: =+F9-F12 -> 487046.92 | G10: =+G9-G12 -> 645936.26 | H10: =+H9-H12 -> 612890.85 | I10: =+I9-I12 -> 499502.71 | J10: =+J9-J12 -> 495184.62 | ... Y10: =+Y9-Y12 -> 474983.88
B11: Tỷ trọng trên tổng nguồn | C11: =+C10/C8 -> #VALUE! | D11: =+D10/D8 -> 0.67418061 | E11: =+E10/E8 -> 0.81235468 | F11: =+F10/F8 -> 0.78180142 | G11: =+G10/G8 -> 0.85667669 | H11: =+H10/H8 -> 0.8334828 | I11: =+I10/I8 -> 0.8240801 | J11: =+J10/J8 -> 0.76795935 | ... Y11: =+Y10/Y8 -> 0.91600193
A12: 2 | B12: Vốn huy động được TW cấp bù | C12: VHD | D12: 214833.38 | E12: 79442.33 | F12: 95595.43 | G12: 73759.12 | H12: 75703.28 | I12: 58395.98 | J12: 75608.15 | K12: 73222.68 | L12: 81547.16 | M12: 60050.21 | N12: 112052.83 | O12: 51268.49 | P12: 66425.94 | Q12: 196849.06 | R12: 46941.34 | S12: 50974.34 | T12: 69384.76 | U12: 52446.01 | V12: 36410.13 | W12: 71189.83 | X12: 55605.52 | Y12: 43456.38
B13: Tỷ trọng trên tổng nguồn | C13: =+C12/C8 -> #VALUE! | D13: =+D12/D8 -> 0.29584808 | E13: =+E12/E8 -> 0.13744179 | F13: =+F12/F8 -> 0.15344855 | G13: =+G12/G8 -> 0.097823458 | H13: =+H12/H8 -> 0.10295044 | I13: =+I12/I8 -> 0.096341749 | J13: =+J12/J8 -> 0.11725725 | ... Y13: =+Y12/Y8 -> 0.083805219
A14: 2.1. | B14: Tiền gửi tổ chức, cá nhân | C14: VHD_TG | D14: 119126.17 | E14: 4343.33 | F14: 4746.26 | G14: 3310.49 | H14: 1933.31 | I14: 4028.12 | J14: 10604.04 | K14: 1187.43 | L14: 7024.9 | M14: 1848.45 | N14: 1238.74 | O14: 793.04 | P14: 2897.85 | Q14: 166922.1 | R14: 3978.34 | S14: 4200.39 | T14: 1930.45 | U14: 2769.96 | V14: 2156.07 | W14: 6276.84 | X14: 4631.32 | Y14: 1815.02
B15: Tr.đó: Tiền gửi ký quỹ đi LĐ HQ | C15: VHD_KQHQ | D15: 9842.7 | E15: 3267.76 | F15: 1571.58 | G15: 525.64 | H15: 1060.92 | I15: 2072.11 | J15: 210.26 | K15: 204.7 | L15: 204.7 | M15: 936.43 | N15: 0 | O15: 0 | P15: 1330.48 | Q15: 2851.04 | R15: 223.12 | S15: 209.4 | T15: 338.43 | U15: 319.66 | V15: 450.9 | W15: 111.31 | X15: 1042.6 | Y15: 680.46
B16: Tiền gửi vay NOXH | C16: VHD_NOXH | D16: 0 | E16: 0 | F16: 0 | G16: 0 | H16: 0 | I16: 0 | J16: 0 | K16: 0 | L16: 0 | M16: 0 | N16: 0 | O16: 0 | P16: 0 | Q16: 0 | R16: 0 | S16: 0 | T16: 0 | U16: 0 | V16: 0 | W16: 0 | X16: 0 | Y16: 0
A17: 2.2. | B17: Huy động tiết kiệm dân cư | C17: VHD_TKDC | D17: 9625.53 | E17: 15627.91 | F17: 11368.76 | G17: 12217.6 | H17: 12528.62 | I17: 20355.06 | J17: 8562.88 | K17: 14963.81 | L17: 25391.11 | M17: 8368.52 | N17: 23941.5 | O17: 10573.39 | P17: 15951.05 | Q17: 12444.25 | R17: 9430.57 | S17: 3072.34 | T17: 15049.6 | U17: 20634.21 | V17: 8663.66 | W17: 17412.33 | X17: 7361.06 | Y17: 7871.54
A18: 2.3. | B18: Huy động tiết kiệm tại ĐGDX | C18: VHD_TKXA | D18: 4329.92 | E18: 1109.91 | F18: 5785.76 | G18: 3668.97 | H18: 6580.87 | I18: 10155.48 | J18: 8003.63 | K18: 2295.47 | L18: 5543.52 | M18: 5549.98 | N18: 2631.31 | O18: 582.85 | P18: 2040.88 | Q18: 0 | R18: 2287.09 | S18: 2496.15 | T18: 1540.69 | U18: 456.47 | V18: 971.76 | W18: 3824.25 | X18: 1073.42 | Y18: 3142.41
A19: 2.4. | B19: Tiền gửi Tổ viên Tổ TKVV | C19: VHD_TKTO | D19: 81189.51 | E19: 58361.18 | F19: 71387.35 | G19: 54342.05 | H19: 54398.48 | I19: 23574.69 | J19: 48324.9 | K19: 54365.95 | L19: 43567.59 | M19: 44061.46 | N19: 84216.28 | O19: 38887.93 | P19: 42736.16 | Q19: 17428.71 | R19: 30969.04 | S19: 39972.46 | T19: 50557.58 | U19: 27730.37 | V19: 23348.64 | W19: 42943.39 | X19: 41932.12 | Y19: 30250.51
A20: II | B20: Vốn nhận UT địa phương | C20: =+C22+C23 -> #VALUE! | D20: =+D22+D23 -> 21764 | E20: =+E22+E23 -> 29018 | F20: =+F22+F23 -> 40338 | G20: =+G22+G23 -> 34307 | H20: =+H22+H23 -> 46743 | I20: =+I22+I23 -> 48235 | J20: =+J22+J23 -> 74013 | ... Y20: =+Y22+Y23 -> 100
B21: Tỷ trọng trên tổng nguồn | C21: =+C20/C8 -> #VALUE! | D21: =+D20/D8 -> 0.029971309 | E21: =+E20/E8 -> 0.050203536 | F21: =+F20/F8 -> 0.064750036 | G21: =+G20/G8 -> 0.045499856 | H21: =+H20/H8 -> 0.063566762 | I21: =+I20/I8 -> 0.079578154 | J21: =+J20/J8 -> 0.1147834 | ... Y21: =+Y20/Y8 -> 0.00019284906
A22: 1 | B22: Vốn ngân sách tỉnh | C22: VONDP_T | D22: 21764 | E22: 29018 | F22: 40338 | G22: 34307 | H22: 46743 | I22: 48235 | J22: 74013 | K22: 69367 | L22: 34142 | M22: 45717 | N22: 31910 | O22: 100 | P22: 100 | Q22: 100 | R22: 100 | S22: 100 | T22: 100 | U22: 100 | V22: 100 | W22: 100 | X22: 100 | Y22: 100
A23: 2 | B23: Vốn ngân sách huyện | C23: VONDP_H | D23: 0 | E23: 0 | F23: 0 | G23: 0 | H23: 0 | I23: 0 | J23: 0 | K23: 0 | L23: 0 | M23: 0 | N23: 0 | O23: 0 | P23: 0 | Q23: 0 | R23: 0 | S23: 0 | T23: 0 | U23: 0 | V23: 0 | W23: 0 | X23: 0 | Y23: 0
A24: III | B24: Nguồn vốn khác | C24: 0 | D24: 0 | E24: 0 | F24: 0 | G24: 0 | H24: 0 | I24: 0 | J24: 0 | K24: 0 | L24: 0 | M24: 0 | N24: 0 | O24: 0 | P24: 0 | Q24: 0 | R24: 0 | S24: 0 | T24: 0 | U24: 0 | V24: 0 | W24: 0 | X24: 0 | Y24: 0
A25: B | B25: SỬ DỤNG VỐN (B1+B2+B3) | C25: =+C26+C82+C83 -> #VALUE! | D25: =+D26+D82+D83 -> 726161.15 | E25: =+E26+E82+E83 -> 578007.1 | F25: =+F26+F82+F83 -> 622980.35 | G25: =+G26+G82+G83 -> 754002.38 | H25: =+H26+H82+H83 -> 735337.13 | I25: =+I26+I82+I83 -> 606133.69 | J25: =+J26+J82+J83 -> 644805.77 | ... Y25: =+Y26+Y82+Y83 -> 518540.26
A26: B1 | B26: TỔNG DƯ NỢ | C26: =+C29+C36 -> #VALUE! | D26: =+D29+D36 -> 715749.14 | E26: =+E29+E36 -> 576460.72 | F26: =+F29+F36 -> 621751.54 | G26: =+G29+G36 -> 752281.88 | H26: =+H29+H36 -> 734066.37 | I26: =+I29+I36 -> 603073.41 | J26: =+J29+J36 -> 643090.33 | ... Y26: =+Y29+Y36 -> 517002.54
B27: So với đầu tháng | C27: =+C30+C37 -> #VALUE! | D27: =+D30+D37 -> 57.21 | E27: =+E30+E37 -> 1646.56 | F27: =+F30+F37 -> 4889.26 | G27: =+G30+G37 -> -5419.88 | H27: =+H30+H37 -> 1348.7 | I27: =+I30+I37 -> 8447.96 | J27: =+J30+J37 -> 1714.26 | ... Y27: =+Y30+Y37 -> 4562.29
B28: So với đầu năm | C28: =+C31+C38 -> #VALUE! | D28: =+D31+D38 -> 38548.19 | E28: =+E31+E38 -> 35476.01 | F28: =+F31+F38 -> 32088.19 | G28: =+G31+G38 -> 24212.46 | H28: =+H31+H38 -> 38815.98 | I28: =+I31+I38 -> 43119.04 | J28: =+J31+J38 -> 26710.07 | ... Y28: =+Y31+Y38 -> 53787.72
A29: I | B29: Dư nợ nguồn vốn TW | C29: DN_NV1 | D29: 380975.04 | E29: 439803.9 | F29: 440246.06 | G29: 469532.59 | H29: 571787.78 | I29: 480224.54 | J29: 454489.65 | K29: 523173.61 | L29: 454838.58 | M29: 433673.4 | N29: 424246.99 | O29: 291539.18 | P29: 728984.73 | Q29: 300461.91 | R29: 313108.62 | S29: 748672.87 | T29: 471788.44 | U29: 375105.04 | V29: 556496.45 | W29: 631755.41 | X29: 609971.04 | Y29: 476093.12
B30: So với đầu tháng | C30: DN_NV1_PRE_M | D30: -5610.95 | E30: 2493.33 | F30: 4001.63 | G30: -5044.73 | H30: 828.44 | I30: 8059.07 | J30: 3299.86 | K30: -977.93 | L30: 4044.47 | M30: 3742.16 | N30: 977.98 | O30: 7878.38 | P30: 14097.71 | Q30: 2821.4 | R30: 6827.33 | S30: 14056.77 | T30: 9185.81 | U30: 4570.2 | V30: 22283.83 | W30: 14438.13 | X30: 1262.78 | Y30: 4643.29
B31: So với đầu năm | C31: DN_NV1_PRE_M | D31: 18025.58 | E31: 30271.64 | F31: 24585.32 | G31: 11753.4 | H31: 32776.77 | I31: 30000.58 | J31: 24064.48 | K31: 24503.4 | L31: 28980.2 | M31: 24383.45 | N31: 27167.07 | O31: 29157.38 | P31: 65183.27 | Q31: 21757.56 | R31: 28344.44 | S31: 67302.48 | T31: 46855.13 | U31: 29891.63 | V31: 59818.17 | W31: 62734.74 | X31: 54974.62 | Y31: 38743.09
B32: Trong đó: Nợ quá hạn | C32: DN_NV1_QH | D32: 1255.26 | E32: 1609.07 | F32: 603.94 | G32: 678.22 | H32: 1101.75 | I32: 612.17 | J32: 209.18 | K32: 702.92 | L32: 277.14 | M32: 689.5 | N32: 742.65 | O32: 12 | P32: 284.75 | Q32: 513.69 | R32: 130.16 | S32: 568.45 | T32: 272.84 | U32: 0 | V32: 611.6 | W32: 199.12 | X32: 239.55 | Y32: 239.64
B33: So với đầu tháng | C33: DN_NV1_PRE_M | D33: -33.47 | E33: 24.26 | F33: 105.13 | G33: 87.75 | H33: 72.95 | I33: 52.5 | J33: 6.5 | K33: -12.5 | L33: 99.75 | M33: 5.78 | N33: 3.8 | O33: 0 | P33: 56.05 | Q33: 114 | R33: 66.76 | S33: 22.67 | T33: -1.4 | U33: 0 | V33: 25.5 | W33: -3.4 | X33: 61.16 | Y33: 0
B34: So với đầu năm | C34: DN_NV1_PRE_M | D34: 8.99 | E34: 206.48 | F34: 69.74 | G34: 6.02 | H34: 1.76 | I34: -166.4 | J34: 24.37 | K34: -174.08 | L34: 79.09 | M34: -5.01 | N34: 54.2 | O34: 0 | P34: -24.86 | Q34: 5.75 | R34: 66.76 | S34: 24.08 | T34: -21.4 | U34: 0 | V34: -40 | W34: -49.66 | X34: 61.12 | Y34: -0.4
B35: Tỷ lệ NQH | C35: =+C32/C29 -> #VALUE! | D35: =+D32/D29 -> 0.0032948615 | E35: =+E32/E29 -> 0.0036586078 | F35: =+F32/F29 -> 0.0013718237 | G35: =+G32/G29 -> 0.0014444578 | H35: =+H32/H29 -> 0.0019268513 | I35: =+I32/I29 -> 0.0012747578 | J35: =+J32/J29 -> 0.00046025251 | ... Y35: =+Y32/Y29 -> 0.00050334691
A36: II | B36: Dư nợ nguồn vốn Địa phương | C36: DN_NV2 | D36: 334774.1 | E36: 136656.82 | F36: 181505.48 | G36: 282749.29 | H36: 162278.59 | I36: 122848.87 | J36: 188600.68 | K36: 190988.71 | L36: 142187.01 | M36: 128921.18 | N36: 143941.41 | O36: 71603 | P36: 38333.2 | Q36: 84727.15 | R36: 64550.39 | S36: 39138.81 | T36: 60849.15 | U36: 52819.6 | V36: 31490.49 | W36: 35604.63 | X36: 44628.7 | Y36: 40909.42
B37: So với đầu tháng | C37: DN_NV1_PRE_M | D37: 5668.16 | E37: -846.77 | F37: 887.63 | G37: -375.15 | H37: 520.26 | I37: 388.89 | J37: -1585.6 | K37: 555.71 | L37: 315.17 | M37: 85.95 | N37: 310.48 | O37: 1000 | P37: 6.1 | Q37: -3.25 | R37: 77 | S37: 734 | T37: 1569.19 | U37: -481.5 | V37: -268.21 | W37: 723.8 | X37: 122.25 | Y37: -81
B38: So với đầu năm | C38: DN_NV1_PRE_M | D38: 20522.61 | E38: 5204.37 | F38: 7502.87 | G38: 12459.06 | H38: 6039.21 | I38: 13118.46 | J38: 2645.59 | K38: 14915.21 | L38: 6440.96 | M38: 9212.73 | N38: 2867.96 | O38: 25410 | P38: 11220.1 | Q38: 15205.77 | R38: 16139.42 | S38: 17128.71 | T38: 25591.79 | U38: 15214.4 | V38: 6486.79 | W38: 12088.11 | X38: 14255.73 | Y38: 15044.63
B39: Trong đó: Nợ quá hạn | C39: DN_NV2_QH | D39: 529.11 | E39: 206.61 | F39: 245.34 | G39: 397.93 | H39: 223.06 | I39: 254.21 | J39: 114.69 | K39: 300.18 | L39: 51.06 | M39: 189.96 | N39: 92.43 | O39: 0 | P39: 4.8 | Q39: 59.2 | R39: 48.29 | S39: 23 | T39: 73.5 | U39: 0 | V39: 35 | W39: 0 | X39: 1.25 | Y39: 0
B40: So với đầu tháng | C40: DN_NV1_PRE_M | D40: 73.12 | E40: -11 | F40: 0 | G40: 75.14 | H40: -0.63 | I40: 0 | J40: 0 | K40: -14.5 | L40: -14 | M40: 0 | N40: -0.94 | O40: 0 | P40: -7.4 | Q40: -2.3 | R40: 0 | S40: 0 | T40: 0 | U40: 0 | V40: 0 | W40: 0 | X40: 1.25 | Y40: 0
...

Sheet TonghopBC
A1: NHCSXH CHI NHÁNH TỈNH ĐỒNG NAI
A3: =Dulieu!A3 -> CÂN ĐỐI NGUỒN VỐN VÀ SỬ DỤNG VỐN NĂM 2026
A4: =Dulieu!A4 -> (Thực hiện đến 21/04/2026)
N5: Đơn vị: triệu đồng, %
A6: TT | B6: Chỉ tiêu | C6: Tổng | D6: Trong đó | O6: Trong đó
D7: HST | E7: Long Thành | F7: Trảng Bom | G7: Long Khánh | H7: Xuân Lộc | I7: Định Quán | J7: Vĩnh Cửu | K7: Tân Phú | L7: Thống Nhất | M7: Cẩm Mỹ | N7: Nhơn Trạch | O7: Bình Long | P7: Lộc Ninh | Q7: Bình Phước | R7: Phước Long | S7: Bù Đăng | T7: Đồng Phú | U7: Chơn Thành | V7: Bù Đốp | W7: Bù Gia Mập | X7: Phú Riềng | Y7: Hớn Quản
A8: A | B8: NGUỒN VỐN (I+II+III) | C8: =SUM(D8:Y8) -> 13197495 | D8: =+D50+D172 -> 726161.15 | E8: =+Dulieu!E8 -> 578007.1 | F8: =+Dulieu!F8 -> 622980.35 | G8: =+Dulieu!G8 -> 754002.38 | H8: =+Dulieu!H8 -> 735337.13 | I8: =+Dulieu!I8 -> 606133.69 | J8: =+Dulieu!J8 -> 644805.77 | K8: =+Dulieu!K8 -> 715752.69 | L8: =+Dulieu!L8 -> 598856.16 | ... Y8: =+Dulieu!Y8 -> 518540.26
B9: So với đầu tháng | C9: =SUM(D9:Y9) -> 136748.86 | D9: =+D51+D173 -> 5050.67 | E9: =+E51+E173 -> 2040.7 | F9: =+F51+F173 -> 5682.33 | G9: =+G51+G173 -> -4368.84 | H9: =+H51+H173 -> 941.6 | I9: =+I51+I173 -> 10386.42 | J9: =+J51+J173 -> 2278.12 | K9: =+K51+K173 -> -586.03 | ... Y9: =+Y51+Y173 -> 4531.73
B10: So với đầu năm | C10: =SUM(D10:Y10) -> 1080222.7 | D10: =+D52+D174 -> 44562.51 | E10: =+E52+E174 -> 36623.98 | F10: =+F52+F174 -> 33229.51 | G10: =+G52+G174 -> 25645.2 | H10: =+H52+H174 -> 39266.49 | I10: =+I52+I174 -> 45682.67 | J10: =+J52+J174 -> 27215.23 | K10: =+K52+K174 -> 40083.06 | ... Y10: =+Y52+Y174 -> 54369.99
A11: I | B11: Vốn Trung ương | C11: =SUM(D11:Y11) -> 12720841 | D11: =+D8-D36 -> 704397.15 | E11: =+E8-E36 -> 548989.1 | F11: =+F8-F36 -> 582642.35 | G11: =+G8-G36 -> 719695.38 | H11: =+H8-H36 -> 688594.13 | I11: =+I8-I36 -> 557898.69 | J11: =+J8-J36 -> 570792.77 | K11: =+K8-K36 -> 646385.69 | ... Y11: =+Y8-Y36 -> 518440.26
B12: So với đầu tháng | C12: =SUM(D12:Y12) -> 136748.86 | D12: =+D9-D37 -> 5050.67 | E12: =+E9-E37 -> 2040.7 | F12: =+F9-F37 -> 5682.33 | G12: =+G9-G37 -> -4368.84 | H12: =+H9-H37 -> 941.6 | I12: =+I9-I37 -> 10386.42 | J12: =+J9-J37 -> 2278.12 | K12: =+K9-K37 -> -586.03 | ... Y12: =+Y9-Y37 -> 4531.73
B13: So với đầu năm | C13: =SUM(D13:Y13) -> #N/A | D13: =+D10-D38 -> #N/A | E13: =+E10-E38 -> #N/A | F13: =+F10-F38 -> #N/A | G13: =+G10-G38 -> #N/A | H13: =+H10-H38 -> #N/A | I13: =+I10-I38 -> #N/A | J13: =+J10-J38 -> #N/A | K13: =+K10-K38 -> #N/A | ... Y13: =+Y10-Y38 -> #N/A
A14: 1 | B14: Vốn trung ương cấp | C14: =SUM(D14:Y14) -> 10979678 | D14: =+D11-D18 -> 489563.77 | E14: =+E11-E18 -> 469546.77 | F14: =+F11-F18 -> 487046.92 | G14: =+G11-G18 -> 645936.26 | H14: =+H11-H18 -> 612890.85 | I14: =+I11-I18 -> 499502.71 | J14: =+J11-J18 -> 495184.62 | K14: =+K11-K18 -> 573163.01 | ... Y14: =+Y11-Y18 -> 474983.88
B15: So với đầu tháng | C15: =SUM(D15:Y15) -> 206560.67 | D15: =+D12-D19 -> 8394.77 | E15: =+E12-E19 -> 4284.56 | F15: =+F12-F19 -> 11658.07 | G15: =+G12-G19 -> -995.82 | H15: =+H12-H19 -> 5617.15 | I15: =+I12-I19 -> 12906.72 | J15: =+J12-J19 -> 6474.48 | K15: =+K12-K19 -> 138.42 | ... Y15: =+Y12-Y19 -> 11383.34
B16: So với đầu năm | C16: =SUM(D16:Y16) -> #N/A | D16: =+D13-D20 -> #N/A | E16: =+E13-E20 -> #N/A | F16: =+F13-F20 -> #N/A | G16: =+G13-G20 -> #N/A | H16: =+H13-H20 -> #N/A | I16: =+I13-I20 -> #N/A | J16: =+J13-J20 -> #N/A | K16: =+K13-K20 -> #N/A | ... Y16: =+Y13-Y20 -> #N/A
B17: Tỷ trọng trên tổng nguồn | C17: =+C14/C8 -> 0.83195172 | D17: =+Dulieu!D11 -> 0.67418061 | E17: =+Dulieu!E11 -> 0.81235468 | F17: =+Dulieu!F11 -> 0.78180142 | G17: =+Dulieu!G11 -> 0.85667669 | H17: =+Dulieu!H11 -> 0.8334828 | I17: =+Dulieu!I11 -> 0.8240801 | J17: =+Dulieu!J11 -> 0.76795935 | K17: =+Dulieu!K11 -> 0.80078359 | ... Y17: =+Dulieu!Y11 -> 0.91600193
A18: 2 | B18: Vốn huy động được TW cấp bù | C18: =SUM(D18:Y18) -> 1741162.4 | D18: =+Dulieu!D12 -> 214833.38 | E18: =+Dulieu!E12 -> 79442.33 | F18: =+Dulieu!F12 -> 95595.43 | G18: =+Dulieu!G12 -> 73759.12 | H18: =+Dulieu!H12 -> 75703.28 | I18: =+Dulieu!I12 -> 58395.98 | J18: =+Dulieu!J12 -> 75608.15 | K18: =+Dulieu!K12 -> 73222.68 | ... Y18: =+Dulieu!Y12 -> 43456.38
B19: So với đầu tháng | C19: =SUM(D19:Y19) -> -69811.81 | D19: =+D18-VLOOKUP(Dulieu!$C$12&"_PRE_M",Dulieu!$C$88:$N$400,2,FALSE) -> -3344.1 | E19: =+E18-VLOOKUP(Dulieu!$C$12&"_PRE_M",Dulieu!$C$88:$N$400,3,FALSE) -> -2243.86 | F19: =+F18-VLOOKUP(Dulieu!$C$12&"_PRE_M",Dulieu!$C$88:$N$400,4,FALSE) -> -5975.74 | G19: =+G18-VLOOKUP(Dulieu!$C$12&"_PRE_M",Dulieu!$C$88:$N$400,5,FALSE) -> -3373.02 | H19: =+H18-VLOOKUP(Dulieu!$C$12&"_PRE_M",Dulieu!$C$88:$N$400,6,FALSE) -> -4675.55 | I19: =+I18-VLOOKUP(Dulieu!$C$12&"_PRE_M",Dulieu!$C$88:$N$400,7,FALSE) -> -2520.3 | J19: =+J18-VLOOKUP(Dulieu!$C$12&"_PRE_M",Dulieu!$C$88:$N$400,8,FALSE) -> -4196.36 | K19: =+K18-VLOOKUP(Dulieu!$C$12&"_PRE_M",Dulieu!$C$88:$N$400,9,FALSE) -> -724.45 | L19: =+L18-VLOOKUP(Dulieu!$C$12&"_PRE_M",Dulieu!$C$88:$N$400,10,FALSE) -> -3733.69 | M19: =+M18-VLOOKUP(Dulieu!$C$12&"_PRE_M",Dulieu!$C$88:$N$400,11,FALSE) -> -1727.74 | N19: =+N18-VLOOKUP(Dulieu!$C$12&"_PRE_M",Dulieu!$C$88:$N$400,12,FALSE) -> 3403.05 | O19: =+O18-VLOOKUP(Dulieu!$C$12&"_PRE_M",Dulieu!$C$88:$Y$400,13,FALSE) -> -2432.74 | P19: =+P18-VLOOKUP(Dulieu!$C$12&"_PRE_M",Dulieu!$C$88:$Y$400,14,FALSE) -> 911.98 | Q19: =+Q18-VLOOKUP(Dulieu!$C$12&"_PRE_M",Dulieu!$C$88:$Y$400,15,FALSE) -> 497.27 | R19: =+R18-VLOOKUP(Dulieu!$C$12&"_PRE_M",Dulieu!$C$88:$Y$400,16,FALSE) -> -3447.66 | S19: =+S18-VLOOKUP(Dulieu!$C$12&"_PRE_M",Dulieu!$C$88:$Y$400,17,FALSE) -> -4554.7 | T19: =+T18-VLOOKUP(Dulieu!$C$12&"_PRE_M",Dulieu!$C$88:$Y$400,18,FALSE) -> -6090.73 | U19: =+U18-VLOOKUP(Dulieu!$C$12&"_PRE_M",Dulieu!$C$88:$Y$400,19,FALSE) -> -6128.03 | V19: =+V18-VLOOKUP(Dulieu!$C$12&"_PRE_M",Dulieu!$C$88:$Y$400,20,FALSE) -> -1673.13 | W19: =+W18-VLOOKUP(Dulieu!$C$12&"_PRE_M",Dulieu!$C$88:$Y$400,21,FALSE) -> -3343.33 | X19: =+X18-VLOOKUP(Dulieu!$C$12&"_PRE_M",Dulieu!$C$88:$Y$400,22,FALSE) -> -7587.37 | Y19: =+Y18-VLOOKUP(Dulieu!$C$12&"_PRE_M",Dulieu!$C$88:$Y$400,23,FALSE) -> -6851.61
B20: So với đầu năm | C20: =SUM(D20:Y20) -> 27309.11 | D20: =+D18-VLOOKUP(Dulieu!$C$12&"_PRE_Y",Dulieu!$C$88:$N$400,2,FALSE) -> -91860.51 | E20: =+E18-VLOOKUP(Dulieu!$C$12&"_PRE_Y",Dulieu!$C$88:$N$400,3,FALSE) -> -1406.77 | F20: =+F18-VLOOKUP(Dulieu!$C$12&"_PRE_Y",Dulieu!$C$88:$N$400,4,FALSE) -> 8150.75 | G20: =+G18-VLOOKUP(Dulieu!$C$12&"_PRE_Y",Dulieu!$C$88:$N$400,5,FALSE) -> 1247.59 | H20: =+H18-VLOOKUP(Dulieu!$C$12&"_PRE_Y",Dulieu!$C$88:$N$400,6,FALSE) -> -1313.84 | I20: =+I18-VLOOKUP(Dulieu!$C$12&"_PRE_Y",Dulieu!$C$88:$N$400,7,FALSE) -> -2052.58 | J20: =+J18-VLOOKUP(Dulieu!$C$12&"_PRE_Y",Dulieu!$C$88:$N$400,8,FALSE) -> 3329.63 | K20: =+K18-VLOOKUP(Dulieu!$C$12&"_PRE_Y",Dulieu!$C$88:$N$400,9,FALSE) -> 7117.99 | L20: =+L18-VLOOKUP(Dulieu!$C$12&"_PRE_Y",Dulieu!$C$88:$N$400,10,FALSE) -> 11772.61 | M20: =+M18-VLOOKUP(Dulieu!$C$12&"_PRE_Y",Dulieu!$C$88:$N$400,11,FALSE) -> -2368.73 | N20: =+N18-VLOOKUP(Dulieu!$C$12&"_PRE_Y",Dulieu!$C$88:$N$400,12,FALSE) -> 19542.44 | O20: =+O18-VLOOKUP(Dulieu!$C$12&"_PRE_Y",Dulieu!$C$88:$Y$400,13,FALSE) -> 5254.31 | P20: =+P18-VLOOKUP(Dulieu!$C$12&"_PRE_Y",Dulieu!$C$88:$Y$400,14,FALSE) -> 11974.46 | Q20: =+Q18-VLOOKUP(Dulieu!$C$12&"_PRE_Y",Dulieu!$C$88:$Y$400,15,FALSE) -> 34560.33 | R20: =+R18-VLOOKUP(Dulieu!$C$12&"_PRE_Y",Dulieu!$C$88:$Y$400,16,FALSE) -> 3846.73 | S20: =+S18-VLOOKUP(Dulieu!$C$12&"_PRE_Y",Dulieu!$C$88:$Y$400,17,FALSE) -> 2533.6 | T20: =+T18-VLOOKUP(Dulieu!$C$12&"_PRE_Y",Dulieu!$C$88:$Y$400,18,FALSE) -> 5008.8 | U20: =+U18-VLOOKUP(Dulieu!$C$12&"_PRE_Y",Dulieu!$C$88:$Y$400,19,FALSE) -> 2104.02 | V20: =+V18-VLOOKUP(Dulieu!$C$12&"_PRE_Y",Dulieu!$C$88:$Y$400,20,FALSE) -> 2934.89 | W20: =+W18-VLOOKUP(Dulieu!$C$12&"_PRE_Y",Dulieu!$C$88:$Y$400,21,FALSE) -> 6725.42 | X20: =+X18-VLOOKUP(Dulieu!$C$12&"_PRE_Y",Dulieu!$C$88:$Y$400,22,FALSE) -> -662.15 | Y20: =+Y18-VLOOKUP(Dulieu!$C$12&"_PRE_Y",Dulieu!$C$88:$Y$400,23,FALSE) -> 870.12
B21: Tỷ trọng trên tổng nguồn | C21: =+C18/C8 -> 0.13193128 | D21: =+Dulieu!D13 -> 0.29584808 | E21: =+Dulieu!E13 -> 0.13744179 | F21: =+Dulieu!F13 -> 0.15344855 | G21: =+Dulieu!G13 -> 0.097823458 | H21: =+Dulieu!H13 -> 0.10295044 | I21: =+Dulieu!I13 -> 0.096341749 | J21: =+Dulieu!J13 -> 0.11725725 | K21: =+Dulieu!K13 -> 0.10230165 | ... Y21: =+Dulieu!Y13 -> 0.083805219
A22: 2.1. | B22: Tiền gửi tổ chức, cá nhân | C22: =SUM(D22:Y22) -> 357762.62 | D22: =+Dulieu!D14 -> 119126.17 | E22: =+Dulieu!E14 -> 4343.33 | F22: =+Dulieu!F14 -> 4746.26 | G22: =+Dulieu!G14 -> 3310.49 | H22: =+Dulieu!H14 -> 1933.31 | I22: =+Dulieu!I14 -> 4028.12 | J22: =+Dulieu!J14 -> 10604.04 | K22: =+Dulieu!K14 -> 1187.43 | ... Y22: =+Dulieu!Y14 -> 1815.02
B23: So với đầu tháng | C23: =SUM(D23:Y23) -> -45728.39 | D23: =+D22-VLOOKUP(Dulieu!$C$14&"_PRE_M",Dulieu!$C$88:$N$400,2,FALSE) -> 767.56 | E23: =+E22-VLOOKUP(Dulieu!$C$14&"_PRE_M",Dulieu!$C$88:$N$400,3,FALSE) -> -1366.69 | F23: =+F22-VLOOKUP(Dulieu!$C$14&"_PRE_M",Dulieu!$C$88:$N$400,4,FALSE) -> -7508.67 | G23: =+G22-VLOOKUP(Dulieu!$C$14&"_PRE_M",Dulieu!$C$88:$N$400,5,FALSE) -> 663.36 | H23: =+H22-VLOOKUP(Dulieu!$C$14&"_PRE_M",Dulieu!$C$88:$N$400,6,FALSE) -> -368.67 | I23: =+I22-VLOOKUP(Dulieu!$C$14&"_PRE_M",Dulieu!$C$88:$N$400,7,FALSE) -> -2434.09 | J23: =+J22-VLOOKUP(Dulieu!$C$14&"_PRE_M",Dulieu!$C$88:$N$400,8,FALSE) -> -451.75 | K23: =+K22-VLOOKUP(Dulieu!$C$14&"_PRE_M",Dulieu!$C$88:$N$400,9,FALSE) -> -251.5 | L23: =+L22-VLOOKUP(Dulieu!$C$14&"_PRE_M",Dulieu!$C$88:$N$400,10,FALSE) -> 49.4 | M23: =+M22-VLOOKUP(Dulieu!$C$14&"_PRE_M",Dulieu!$C$88:$N$400,11,FALSE) -> 76.55 | N23: =+N22-VLOOKUP(Dulieu!$C$14&"_PRE_M",Dulieu!$C$88:$N$400,12,FALSE) -> 114.34 | O23: =+O22-VLOOKUP(Dulieu!$C$14&"_PRE_M",Dulieu!$C$88:$Y$400,13,FALSE) -> -994.59 | P23: =+P22-VLOOKUP(Dulieu!$C$14&"_PRE_M",Dulieu!$C$88:$Y$400,14,FALSE) -> -868.07 | Q23: =+Q22-VLOOKUP(Dulieu!$C$14&"_PRE_M",Dulieu!$C$88:$Y$400,15,FALSE) -> 576.32 | R23: =+R22-VLOOKUP(Dulieu!$C$14&"_PRE_M",Dulieu!$C$88:$Y$400,16,FALSE) -> -3882.89 | S23: =+S22-VLOOKUP(Dulieu!$C$14&"_PRE_M",Dulieu!$C$88:$Y$400,17,FALSE) -> -3590.58 | T23: =+T22-VLOOKUP(Dulieu!$C$14&"_PRE_M",Dulieu!$C$88:$Y$400,18,FALSE) -> -4224.44 | U23: =+U22-VLOOKUP(Dulieu!$C$14&"_PRE_M",Dulieu!$C$88:$Y$400,19,FALSE) -> -5980.99 | V23: =+V22-VLOOKUP(Dulieu!$C$14&"_PRE_M",Dulieu!$C$88:$Y$400,20,FALSE) -> -3754.33 | W23: =+W22-VLOOKUP(Dulieu!$C$14&"_PRE_M",Dulieu!$C$88:$Y$400,21,FALSE) -> -1416.48 | X23: =+X22-VLOOKUP(Dulieu!$C$14&"_PRE_M",Dulieu!$C$88:$Y$400,22,FALSE) -> -6061.03 | Y23: =+Y22-VLOOKUP(Dulieu!$C$14&"_PRE_M",Dulieu!$C$88:$Y$400,23,FALSE) -> -4821.15
B24: So với đầu năm | C24: =SUM(D24:Y24) -> -88589.24 | D24: =+D22-VLOOKUP(Dulieu!$C$14&"_PRE_Y",Dulieu!$C$88:$N$400,2,FALSE) -> -105699.14 | E24: =+E22-VLOOKUP(Dulieu!$C$14&"_PRE_Y",Dulieu!$C$88:$N$400,3,FALSE) -> 10.55 | F24: =+F22-VLOOKUP(Dulieu!$C$14&"_PRE_Y",Dulieu!$C$88:$N$400,4,FALSE) -> -5715.87 | G24: =+G22-VLOOKUP(Dulieu!$C$14&"_PRE_Y",Dulieu!$C$88:$N$400,5,FALSE) -> 447.05 | H24: =+H22-VLOOKUP(Dulieu!$C$14&"_PRE_Y",Dulieu!$C$88:$N$400,6,FALSE) -> -701.62 | I24: =+I22-VLOOKUP(Dulieu!$C$14&"_PRE_Y",Dulieu!$C$88:$N$400,7,FALSE) -> -165.62 | J24: =+J22-VLOOKUP(Dulieu!$C$14&"_PRE_Y",Dulieu!$C$88:$N$400,8,FALSE) -> -102.22 | K24: =+K22-VLOOKUP(Dulieu!$C$14&"_PRE_Y",Dulieu!$C$88:$N$400,9,FALSE) -> 41.98 | L24: =+L22-VLOOKUP(Dulieu!$C$14&"_PRE_Y",Dulieu!$C$88:$N$400,10,FALSE) -> 2567.32 | M24: =+M22-VLOOKUP(Dulieu!$C$14&"_PRE_Y",Dulieu!$C$88:$N$400,11,FALSE) -> -255.65 | N24: =+N22-VLOOKUP(Dulieu!$C$14&"_PRE_Y",Dulieu!$C$88:$N$400,12,FALSE) -> -417.35 | O24: =+O22-VLOOKUP(Dulieu!$C$14&"_PRE_Y",Dulieu!$C$88:$Y$400,13,FALSE) -> -49.7 | P24: =+P22-VLOOKUP(Dulieu!$C$14&"_PRE_Y",Dulieu!$C$88:$Y$400,14,FALSE) -> 746.64 | Q24: =+Q22-VLOOKUP(Dulieu!$C$14&"_PRE_Y",Dulieu!$C$88:$Y$400,15,FALSE) -> 30301.79 | R24: =+R22-VLOOKUP(Dulieu!$C$14&"_PRE_Y",Dulieu!$C$88:$Y$400,16,FALSE) -> -395.6 | S24: =+S22-VLOOKUP(Dulieu!$C$14&"_PRE_Y",Dulieu!$C$88:$Y$400,17,FALSE) -> -1207.3 | T24: =+T22-VLOOKUP(Dulieu!$C$14&"_PRE_Y",Dulieu!$C$88:$Y$400,18,FALSE) -> -413.58 | U24: =+U22-VLOOKUP(Dulieu!$C$14&"_PRE_Y",Dulieu!$C$88:$Y$400,19,FALSE) -> 637.32 | V24: =+V22-VLOOKUP(Dulieu!$C$14&"_PRE_Y",Dulieu!$C$88:$Y$400,20,FALSE) -> -2280.99 | W24: =+W22-VLOOKUP(Dulieu!$C$14&"_PRE_Y",Dulieu!$C$88:$Y$400,21,FALSE) -> -1381.35 | X24: =+X22-VLOOKUP(Dulieu!$C$14&"_PRE_Y",Dulieu!$C$88:$Y$400,22,FALSE) -> -3722.43 | Y24: =+Y22-VLOOKUP(Dulieu!$C$14&"_PRE_Y",Dulieu!$C$88:$Y$400,23,FALSE) -> -833.47
B25: Tr.đó: Tiền gửi ký quỹ đi LĐ HQ | C25: =SUM(D25:Y25) -> 27454.2 | D25: =+Dulieu!D15 -> 9842.7 | E25: =+Dulieu!E15 -> 3267.76 | F25: =+Dulieu!F15 -> 1571.58 | G25: =+Dulieu!G15 -> 525.64 | H25: =+Dulieu!H15 -> 1060.92 | I25: =+Dulieu!I15 -> 2072.11 | J25: =+Dulieu!J15 -> 210.26 | K25: =+Dulieu!K15 -> 204.7 | ... Y25: =+Dulieu!Y15 -> 680.46
B26: Tiền gửi vay NOXH | C26: =SUM(D26:Y26) -> 0 | D26: =+Dulieu!D16 -> 0 | E26: =+Dulieu!E16 -> 0 | F26: =+Dulieu!F16 -> 0 | G26: =+Dulieu!G16 -> 0 | H26: =+Dulieu!H16 -> 0 | I26: =+Dulieu!I16 -> 0 | J26: =+Dulieu!J16 -> 0 | K26: =+Dulieu!K16 -> 0 | ... Y26: =+Dulieu!Y16 -> 0
A27: 2.2. | B27: Huy động tiết kiệm dân cư | C27: =SUM(D27:Y27) -> 291415.3 | D27: =+Dulieu!D17 -> 9625.53 | E27: =+Dulieu!E17 -> 15627.91 | F27: =+Dulieu!F17 -> 11368.76 | G27: =+Dulieu!G17 -> 12217.6 | H27: =+Dulieu!H17 -> 12528.62 | I27: =+Dulieu!I17 -> 20355.06 | J27: =+Dulieu!J17 -> 8562.88 | K27: =+Dulieu!K17 -> 14963.81 | ... Y27: =+Dulieu!Y17 -> 7871.54
B28: So với đầu tháng | C28: =SUM(D28:Y28) -> -9569.08 | D28: =+D27-VLOOKUP(Dulieu!$C$17&"_PRE_M",Dulieu!$C$88:$N$400,2,FALSE) -> 29.33 | E28: =+E27-VLOOKUP(Dulieu!$C$17&"_PRE_M",Dulieu!$C$88:$N$400,3,FALSE) -> -644.75 | F28: =+F27-VLOOKUP(Dulieu!$C$17&"_PRE_M",Dulieu!$C$88:$N$400,4,FALSE) -> 117.85 | G28: =+G27-VLOOKUP(Dulieu!$C$17&"_PRE_M",Dulieu!$C$88:$N$400,5,FALSE) -> 185.26 | H28: =+H27-VLOOKUP(Dulieu!$C$17&"_PRE_M",Dulieu!$C$88:$N$400,6,FALSE) -> 100.34 | I28: =+I27-VLOOKUP(Dulieu!$C$17&"_PRE_M",Dulieu!$C$88:$N$400,7,FALSE) -> 56.35 | J28: =+J27-VLOOKUP(Dulieu!$C$17&"_PRE_M",Dulieu!$C$88:$N$400,8,FALSE) -> -2109.28 | K28: =+K27-VLOOKUP(Dulieu!$C$17&"_PRE_M",Dulieu!$C$88:$N$400,9,FALSE) -> 593.31 | L28: =+L27-VLOOKUP(Dulieu!$C$17&"_PRE_M",Dulieu!$C$88:$N$400,10,FALSE) -> 9.14 | M28: =+M27-VLOOKUP(Dulieu!$C$17&"_PRE_M",Dulieu!$C$88:$N$400,11,FALSE) -> -159.28 | N28: =+N27-VLOOKUP(Dulieu!$C$17&"_PRE_M",Dulieu!$C$88:$N$400,12,FALSE) -> 773.56 | O28: =+O27-VLOOKUP(Dulieu!$C$17&"_PRE_M",Dulieu!$C$88:$Y$400,13,FALSE) -> -2715.97 | P28: =+P27-VLOOKUP(Dulieu!$C$17&"_PRE_M",Dulieu!$C$88:$Y$400,14,FALSE) -> -2438.54 | Q28: =+Q27-VLOOKUP(Dulieu!$C$17&"_PRE_M",Dulieu!$C$88:$Y$400,15,FALSE) -> -376.85 | R28: =+R27-VLOOKUP(Dulieu!$C$17&"_PRE_M",Dulieu!$C$88:$Y$400,16,FALSE) -> -459.1 | S28: =+S27-VLOOKUP(Dulieu!$C$17&"_PRE_M",Dulieu!$C$88:$Y$400,17,FALSE) -> -279.94 | T28: =+T27-VLOOKUP(Dulieu!$C$17&"_PRE_M",Dulieu!$C$88:$Y$400,18,FALSE) -> 199 | U28: =+U27-VLOOKUP(Dulieu!$C$17&"_PRE_M",Dulieu!$C$88:$Y$400,19,FALSE) -> -1455.23 | V28: =+V27-VLOOKUP(Dulieu!$C$17&"_PRE_M",Dulieu!$C$88:$Y$400,20,FALSE) -> 30.48 | W28: =+W27-VLOOKUP(Dulieu!$C$17&"_PRE_M",Dulieu!$C$88:$Y$400,21,FALSE) -> -296.1 | X28: =+X27-VLOOKUP(Dulieu!$C$17&"_PRE_M",Dulieu!$C$88:$Y$400,22,FALSE) -> -492.75 | Y28: =+Y27-VLOOKUP(Dulieu!$C$17&"_PRE_M",Dulieu!$C$88:$Y$400,23,FALSE) -> -235.91
B29: So với đầu năm | C29: =SUM(D29:Y29) -> -9900.1 | D29: =+D27-VLOOKUP(Dulieu!$C$17&"_PRE_Y",Dulieu!$C$88:$N$400,2,FALSE) -> -1135.66 | E29: =+E27-VLOOKUP(Dulieu!$C$17&"_PRE_Y",Dulieu!$C$88:$N$400,3,FALSE) -> -988.77 | F29: =+F27-VLOOKUP(Dulieu!$C$17&"_PRE_Y",Dulieu!$C$88:$N$400,4,FALSE) -> -660.55 | G29: =+G27-VLOOKUP(Dulieu!$C$17&"_PRE_Y",Dulieu!$C$88:$N$400,5,FALSE) -> -2851.12 | H29: =+H27-VLOOKUP(Dulieu!$C$17&"_PRE_Y",Dulieu!$C$88:$N$400,6,FALSE) -> -889.43 | I29: =+I27-VLOOKUP(Dulieu!$C$17&"_PRE_Y",Dulieu!$C$88:$N$400,7,FALSE) -> -1750.76 | J29: =+J27-VLOOKUP(Dulieu!$C$17&"_PRE_Y",Dulieu!$C$88:$N$400,8,FALSE) -> -2452.19 | K29: =+K27-VLOOKUP(Dulieu!$C$17&"_PRE_Y",Dulieu!$C$88:$N$400,9,FALSE) -> 3346.55 | L29: =+L27-VLOOKUP(Dulieu!$C$17&"_PRE_Y",Dulieu!$C$88:$N$400,10,FALSE) -> 1803.26 | M29: =+M27-VLOOKUP(Dulieu!$C$17&"_PRE_Y",Dulieu!$C$88:$N$400,11,FALSE) -> -4489 | N29: =+N27-VLOOKUP(Dulieu!$C$17&"_PRE_Y",Dulieu!$C$88:$N$400,12,FALSE) -> 7259.36 | O29: =+O27-VLOOKUP(Dulieu!$C$17&"_PRE_Y",Dulieu!$C$88:$Y$400,13,FALSE) -> -1074.91 | P29: =+P27-VLOOKUP(Dulieu!$C$17&"_PRE_Y",Dulieu!$C$88:$Y$400,14,FALSE) -> 592.7 | Q29: =+Q27-VLOOKUP(Dulieu!$C$17&"_PRE_Y",Dulieu!$C$88:$Y$400,15,FALSE) -> 1002.12 | R29: =+R27-VLOOKUP(Dulieu!$C$17&"_PRE_Y",Dulieu!$C$88:$Y$400,16,FALSE) -> -2870.63 | S29: =+S27-VLOOKUP(Dulieu!$C$17&"_PRE_Y",Dulieu!$C$88:$Y$400,17,FALSE) -> -652.02 | T29: =+T27-VLOOKUP(Dulieu!$C$17&"_PRE_Y",Dulieu!$C$88:$Y$400,18,FALSE) -> -460.81 | U29: =+U27-VLOOKUP(Dulieu!$C$17&"_PRE_Y",Dulieu!$C$88:$Y$400,19,FALSE) -> -4753.1 | V29: =+V27-VLOOKUP(Dulieu!$C$17&"_PRE_Y",Dulieu!$C$88:$Y$400,20,FALSE) -> 254.42 | W29: =+W27-VLOOKUP(Dulieu!$C$17&"_PRE_Y",Dulieu!$C$88:$Y$400,21,FALSE) -> 1980.55 | X29: =+X27-VLOOKUP(Dulieu!$C$17&"_PRE_Y",Dulieu!$C$88:$Y$400,22,FALSE) -> 188.17 | Y29: =+Y27-VLOOKUP(Dulieu!$C$17&"_PRE_Y",Dulieu!$C$88:$Y$400,23,FALSE) -> -1298.28
A30: 2.3. | B30: Huy động tiết kiệm tại ĐGDX | C30: =SUM(D30:Y30) -> 74070.79 | D30: =+Dulieu!D18 -> 4329.92 | E30: =+Dulieu!E18 -> 1109.91 | F30: =+Dulieu!F18 -> 5785.76 | G30: =+Dulieu!G18 -> 3668.97 | H30: =+Dulieu!H18 -> 6580.87 | I30: =+Dulieu!I18 -> 10155.48 | J30: =+Dulieu!J18 -> 8003.63 | K30: =+Dulieu!K18 -> 2295.47 | ... Y30: =+Dulieu!Y18 -> 3142.41
B31: So với đầu tháng | C31: =SUM(D31:Y31) -> 190.18 | D31: =+D30-VLOOKUP(Dulieu!$C$18&"_PRE_M",Dulieu!$C$88:$N$400,2,FALSE) -> 1.46 | E31: =+E30-VLOOKUP(Dulieu!$C$18&"_PRE_M",Dulieu!$C$88:$N$400,3,FALSE) -> -182.82 | F31: =+F30-VLOOKUP(Dulieu!$C$18&"_PRE_M",Dulieu!$C$88:$N$400,4,FALSE) -> -89.02 | G31: =+G30-VLOOKUP(Dulieu!$C$18&"_PRE_M",Dulieu!$C$88:$N$400,5,FALSE) -> 518.22 | H31: =+H30-VLOOKUP(Dulieu!$C$18&"_PRE_M",Dulieu!$C$88:$N$400,6,FALSE) -> -165.11 | I31: =+I30-VLOOKUP(Dulieu!$C$18&"_PRE_M",Dulieu!$C$88:$N$400,7,FALSE) -> -92.61 | J31: =+J30-VLOOKUP(Dulieu!$C$18&"_PRE_M",Dulieu!$C$88:$N$400,8,FALSE) -> 12.65 | K31: =+K30-VLOOKUP(Dulieu!$C$18&"_PRE_M",Dulieu!$C$88:$N$400,9,FALSE) -> -30.79 | L31: =+L30-VLOOKUP(Dulieu!$C$18&"_PRE_M",Dulieu!$C$88:$N$400,10,FALSE) -> 88.09 | M31: =+M30-VLOOKUP(Dulieu!$C$18&"_PRE_M",Dulieu!$C$88:$N$400,11,FALSE) -> -157.27 | N31: =+N30-VLOOKUP(Dulieu!$C$18&"_PRE_M",Dulieu!$C$88:$N$400,12,FALSE) -> 245.72 | O31: =+O30-VLOOKUP(Dulieu!$C$18&"_PRE_M",Dulieu!$C$88:$Y$400,13,FALSE) -> 0.01 | P31: =+P30-VLOOKUP(Dulieu!$C$18&"_PRE_M",Dulieu!$C$88:$Y$400,14,FALSE) -> 934.65 | Q31: =+Q30-VLOOKUP(Dulieu!$C$18&"_PRE_M",Dulieu!$C$88:$Y$400,15,FALSE) -> 0 | R31: =+R30-VLOOKUP(Dulieu!$C$18&"_PRE_M",Dulieu!$C$88:$Y$400,16,FALSE) -> -340.95 | S31: =+S30-VLOOKUP(Dulieu!$C$18&"_PRE_M",Dulieu!$C$88:$Y$400,17,FALSE) -> -1803.8 | T31: =+T30-VLOOKUP(Dulieu!$C$18&"_PRE_M",Dulieu!$C$88:$Y$400,18,FALSE) -> 135.96 | U31: =+U30-VLOOKUP(Dulieu!$C$18&"_PRE_M",Dulieu!$C$88:$Y$400,19,FALSE) -> 100.05 | V31: =+V30-VLOOKUP(Dulieu!$C$18&"_PRE_M",Dulieu!$C$88:$Y$400,20,FALSE) -> -7.02 | W31: =+W30-VLOOKUP(Dulieu!$C$18&"_PRE_M",Dulieu!$C$88:$Y$400,21,FALSE) -> 505.06 | X31: =+X30-VLOOKUP(Dulieu!$C$18&"_PRE_M",Dulieu!$C$88:$Y$400,22,FALSE) -> 341.12 | Y31: =+Y30-VLOOKUP(Dulieu!$C$18&"_PRE_M",Dulieu!$C$88:$Y$400,23,FALSE) -> 176.58
B32: So với đầu năm | C32: =SUM(D32:Y32) -> -14368.44 | D32: =+D30-VLOOKUP(Dulieu!$C$18&"_PRE_Y",Dulieu!$C$88:$N$400,2,FALSE) -> -353.44 | E32: =+E30-VLOOKUP(Dulieu!$C$18&"_PRE_Y",Dulieu!$C$88:$N$400,3,FALSE) -> -965.67 | F32: =+F30-VLOOKUP(Dulieu!$C$18&"_PRE_Y",Dulieu!$C$88:$N$400,4,FALSE) -> 5.18 | G32: =+G30-VLOOKUP(Dulieu!$C$18&"_PRE_Y",Dulieu!$C$88:$N$400,5,FALSE) -> 632.08 | H32: =+H30-VLOOKUP(Dulieu!$C$18&"_PRE_Y",Dulieu!$C$88:$N$400,6,FALSE) -> -1865.18 | I32: =+I30-VLOOKUP(Dulieu!$C$18&"_PRE_Y",Dulieu!$C$88:$N$400,7,FALSE) -> -614.5 | J32: =+J30-VLOOKUP(Dulieu!$C$18&"_PRE_Y",Dulieu!$C$88:$N$400,8,FALSE) -> -1001.92 | K32: =+K30-VLOOKUP(Dulieu!$C$18&"_PRE_Y",Dulieu!$C$88:$N$400,9,FALSE) -> -1383.74 | L32: =+L30-VLOOKUP(Dulieu!$C$18&"_PRE_Y",Dulieu!$C$88:$N$400,10,FALSE) -> -519.78 | M32: =+M30-VLOOKUP(Dulieu!$C$18&"_PRE_Y",Dulieu!$C$88:$N$400,11,FALSE) -> -1163.9 | N32: =+N30-VLOOKUP(Dulieu!$C$18&"_PRE_Y",Dulieu!$C$88:$N$400,12,FALSE) -> -1596.02 | O32: =+O30-VLOOKUP(Dulieu!$C$18&"_PRE_Y",Dulieu!$C$88:$Y$400,13,FALSE) -> -2105.72 | P32: =+P30-VLOOKUP(Dulieu!$C$18&"_PRE_Y",Dulieu!$C$88:$Y$400,14,FALSE) -> 564.71 | Q32: =+Q30-VLOOKUP(Dulieu!$C$18&"_PRE_Y",Dulieu!$C$88:$Y$400,15,FALSE) -> 0 | R32: =+R30-VLOOKUP(Dulieu!$C$18&"_PRE_Y",Dulieu!$C$88:$Y$400,16,FALSE) -> 217.33 | S32: =+S30-VLOOKUP(Dulieu!$C$18&"_PRE_Y",Dulieu!$C$88:$Y$400,17,FALSE) -> -2907.04 | T32: =+T30-VLOOKUP(Dulieu!$C$18&"_PRE_Y",Dulieu!$C$88:$Y$400,18,FALSE) -> -1135.28 | U32: =+U30-VLOOKUP(Dulieu!$C$18&"_PRE_Y",Dulieu!$C$88:$Y$400,19,FALSE) -> -14.84 | V32: =+V30-VLOOKUP(Dulieu!$C$18&"_PRE_Y",Dulieu!$C$88:$Y$400,20,FALSE) -> -380.96 | W32: =+W30-VLOOKUP(Dulieu!$C$18&"_PRE_Y",Dulieu!$C$88:$Y$400,21,FALSE) -> 891.83 | X32: =+X30-VLOOKUP(Dulieu!$C$18&"_PRE_Y",Dulieu!$C$88:$Y$400,22,FALSE) -> -229.37 | Y32: =+Y30-VLOOKUP(Dulieu!$C$18&"_PRE_Y",Dulieu!$C$88:$Y$400,23,FALSE) -> -442.21
A33: 2.4. | B33: Tiền gửi Tổ viên Tổ TKVV | C33: =SUM(D33:Y33) -> 1004546.4 | D33: =+Dulieu!D19 -> 81189.51 | E33: =+Dulieu!E19 -> 58361.18 | F33: =+Dulieu!F19 -> 71387.35 | G33: =+Dulieu!G19 -> 54342.05 | H33: =+Dulieu!H19 -> 54398.48 | I33: =+Dulieu!I19 -> 23574.69 | J33: =+Dulieu!J19 -> 48324.9 | K33: =+Dulieu!K19 -> 54365.95 | ... Y33: =+Dulieu!Y19 -> 30250.51
B34: So với đầu tháng | C34: =SUM(D34:Y34) -> -22861.61 | D34: =+D33-VLOOKUP(Dulieu!$C$19&"_PRE_M",Dulieu!$C$88:$N$400,2,FALSE) -> -4596.26 | E34: =+E33-VLOOKUP(Dulieu!$C$19&"_PRE_M",Dulieu!$C$88:$N$400,3,FALSE) -> -19.6 | F34: =+F33-VLOOKUP(Dulieu!$C$19&"_PRE_M",Dulieu!$C$88:$N$400,4,FALSE) -> 253.02 | G34: =+G33-VLOOKUP(Dulieu!$C$19&"_PRE_M",Dulieu!$C$88:$N$400,5,FALSE) -> -4774.19 | H34: =+H33-VLOOKUP(Dulieu!$C$19&"_PRE_M",Dulieu!$C$88:$N$400,6,FALSE) -> -4467.04 | I34: =+I33-VLOOKUP(Dulieu!$C$19&"_PRE_M",Dulieu!$C$88:$N$400,7,FALSE) -> -149.95 | J34: =+J33-VLOOKUP(Dulieu!$C$19&"_PRE_M",Dulieu!$C$88:$N$400,8,FALSE) -> -1640.07 | K34: =+K33-VLOOKUP(Dulieu!$C$19&"_PRE_M",Dulieu!$C$88:$N$400,9,FALSE) -> -1035.49 | L34: =+L33-VLOOKUP(Dulieu!$C$19&"_PRE_M",Dulieu!$C$88:$N$400,10,FALSE) -> -3870.32 | M34: =+M33-VLOOKUP(Dulieu!$C$19&"_PRE_M",Dulieu!$C$88:$N$400,11,FALSE) -> -1539.74 | N34: =+N33-VLOOKUP(Dulieu!$C$19&"_PRE_M",Dulieu!$C$88:$N$400,12,FALSE) -> 2279.43 | O34: =+O33-VLOOKUP(Dulieu!$C$19&"_PRE_M",Dulieu!$C$88:$Y$400,13,FALSE) -> 1307.8 | P34: =+P33-VLOOKUP(Dulieu!$C$19&"_PRE_M",Dulieu!$C$88:$Y$400,14,FALSE) -> 483.94 | Q34: =+Q33-VLOOKUP(Dulieu!$C$19&"_PRE_M",Dulieu!$C$88:$Y$400,15,FALSE) -> 297.8 | R34: =+R33-VLOOKUP(Dulieu!$C$19&"_PRE_M",Dulieu!$C$88:$Y$400,16,FALSE) -> 1171.06 | S34: =+S33-VLOOKUP(Dulieu!$C$19&"_PRE_M",Dulieu!$C$88:$Y$400,17,FALSE) -> 702.62 | T34: =+T33-VLOOKUP(Dulieu!$C$19&"_PRE_M",Dulieu!$C$88:$Y$400,18,FALSE) -> -2264.25 | U34: =+U33-VLOOKUP(Dulieu!$C$19&"_PRE_M",Dulieu!$C$88:$Y$400,19,FALSE) -> 403.14 | V34: =+V33-VLOOKUP(Dulieu!$C$19&"_PRE_M",Dulieu!$C$88:$Y$400,20,FALSE) -> 787.74 | W34: =+W33-VLOOKUP(Dulieu!$C$19&"_PRE_M",Dulieu!$C$88:$Y$400,21,FALSE) -> -2235.81 | X34: =+X33-VLOOKUP(Dulieu!$C$19&"_PRE_M",Dulieu!$C$88:$Y$400,22,FALSE) -> -1812.31 | Y34: =+Y33-VLOOKUP(Dulieu!$C$19&"_PRE_M",Dulieu!$C$88:$Y$400,23,FALSE) -> -2143.13
B35: So với đầu năm | C35: =SUM(D35:Y35) -> 126799.6 | D35: =+D33-VLOOKUP(Dulieu!$C$19&"_PRE_Y",Dulieu!$C$88:$N$400,2,FALSE) -> 14765.48 | E35: =+E33-VLOOKUP(Dulieu!$C$19&"_PRE_Y",Dulieu!$C$88:$N$400,3,FALSE) -> 537.12 | F35: =+F33-VLOOKUP(Dulieu!$C$19&"_PRE_Y",Dulieu!$C$88:$N$400,4,FALSE) -> 12214.69 | G35: =+G33-VLOOKUP(Dulieu!$C$19&"_PRE_Y",Dulieu!$C$88:$N$400,5,FALSE) -> 2799.57 | H35: =+H33-VLOOKUP(Dulieu!$C$19&"_PRE_Y",Dulieu!$C$88:$N$400,6,FALSE) -> 1880.39 | I35: =+I33-VLOOKUP(Dulieu!$C$19&"_PRE_Y",Dulieu!$C$88:$N$400,7,FALSE) -> 195.67 | J35: =+J33-VLOOKUP(Dulieu!$C$19&"_PRE_Y",Dulieu!$C$88:$N$400,8,FALSE) -> 6773.26 | K35: =+K33-VLOOKUP(Dulieu!$C$19&"_PRE_Y",Dulieu!$C$88:$N$400,9,FALSE) -> 4703.18 | L35: =+L33-VLOOKUP(Dulieu!$C$19&"_PRE_Y",Dulieu!$C$88:$N$400,10,FALSE) -> 7901.77 | M35: =+M33-VLOOKUP(Dulieu!$C$19&"_PRE_Y",Dulieu!$C$88:$N$400,11,FALSE) -> 3318.02 | N35: =+N33-VLOOKUP(Dulieu!$C$19&"_PRE_Y",Dulieu!$C$88:$N$400,12,FALSE) -> 14271.45 | O35: =+O33-VLOOKUP(Dulieu!$C$19&"_PRE_Y",Dulieu!$C$88:$Y$400,13,FALSE) -> 8053.36 | P35: =+P33-VLOOKUP(Dulieu!$C$19&"_PRE_Y",Dulieu!$C$88:$Y$400,14,FALSE) -> 7270.41 | Q35: =+Q33-VLOOKUP(Dulieu!$C$19&"_PRE_Y",Dulieu!$C$88:$Y$400,15,FALSE) -> 3202.42 | R35: =+R33-VLOOKUP(Dulieu!$C$19&"_PRE_Y",Dulieu!$C$88:$Y$400,16,FALSE) -> 6619.33 | S35: =+S33-VLOOKUP(Dulieu!$C$19&"_PRE_Y",Dulieu!$C$88:$Y$400,17,FALSE) -> 6066.96 | T35: =+T33-VLOOKUP(Dulieu!$C$19&"_PRE_Y",Dulieu!$C$88:$Y$400,18,FALSE) -> 6712.03 | U35: =+U33-VLOOKUP(Dulieu!$C$19&"_PRE_Y",Dulieu!$C$88:$Y$400,19,FALSE) -> 5379.64 | V35: =+V33-VLOOKUP(Dulieu!$C$19&"_PRE_Y",Dulieu!$C$88:$Y$400,20,FALSE) -> 4072.42 | W35: =+W33-VLOOKUP(Dulieu!$C$19&"_PRE_Y",Dulieu!$C$88:$Y$400,21,FALSE) -> 4501.37 | X35: =+X33-VLOOKUP(Dulieu!$C$19&"_PRE_Y",Dulieu!$C$88:$Y$400,22,FALSE) -> 2493.88 | Y35: =+Y33-VLOOKUP(Dulieu!$C$19&"_PRE_Y",Dulieu!$C$88:$Y$400,23,FALSE) -> 3067.18
A36: II | B36: Vốn nhận UT địa phương | C36: =SUM(D36:Y36) -> 476654 | D36: =+Dulieu!D20 -> 21764 | E36: =+Dulieu!E20 -> 29018 | F36: =+Dulieu!F20 -> 40338 | G36: =+Dulieu!G20 -> 34307 | H36: =+Dulieu!H20 -> 46743 | I36: =+Dulieu!I20 -> 48235 | J36: =+Dulieu!J20 -> 74013 | K36: =+Dulieu!K20 -> 69367 | ... Y36: =+Dulieu!Y20 -> 100
B37: So với đầu tháng | C37: =+C41+C44 -> 0 | D37: =+D41+D44 -> 0 | E37: =+E41+E44 -> 0 | F37: =+F41+F44 -> 0 | G37: =+G41+G44 -> 0 | H37: =+H41+H44 -> 0 | I37: =+I41+I44 -> 0 | J37: =+J41+J44 -> 0 | ... Y37: =+Y41+Y44 -> 0
B38: So với đầu năm | C38: =+C42+C45 -> #N/A | D38: =+D42+D45 -> #N/A | E38: =+E42+E45 -> #N/A | F38: =+F42+F45 -> #N/A | G38: =+G42+G45 -> #N/A | H38: =+H42+H45 -> #N/A | I38: =+I42+I45 -> #N/A | J38: =+J42+J45 -> #N/A | ... Y38: =+Y42+Y45 -> #N/A
B39: Tỷ trọng trên tổng nguồn | C39: =+C36/C8 -> 0.036117006 | D39: =+Dulieu!D21 -> 0.029971309 | E39: =+Dulieu!E21 -> 0.050203536 | F39: =+Dulieu!F21 -> 0.064750036 | G39: =+Dulieu!G21 -> 0.045499856 | H39: =+Dulieu!H21 -> 0.063566762 | I39: =+Dulieu!I21 -> 0.079578154 | J39: =+Dulieu!J21 -> 0.1147834 | K39: =+Dulieu!K21 -> 0.09691476 | ... Y39: =+Dulieu!Y21 -> 0.00019284906
A40: 1 | B40: Vốn ngân sách tỉnh | C40: =SUM(D40:Y40) -> 476654 | D40: =+Dulieu!D22 -> 21764 | E40: =+Dulieu!E22 -> 29018 | F40: =+Dulieu!F22 -> 40338 | G40: =+Dulieu!G22 -> 34307 | H40: =+Dulieu!H22 -> 46743 | I40: =+Dulieu!I22 -> 48235 | J40: =+Dulieu!J22 -> 74013 | K40: =+Dulieu!K22 -> 69367 | ... Y40: =+Dulieu!Y22 -> 100
B41: So với đầu tháng | C41: =SUM(D41:Y41) -> 0 | D41: =+D40-VLOOKUP(Dulieu!$C$22&"_PRE_M",Dulieu!$C$88:$N$400,2,FALSE) -> 0 | E41: =+E40-VLOOKUP(Dulieu!$C$22&"_PRE_M",Dulieu!$C$88:$N$400,3,FALSE) -> 0 | F41: =+F40-VLOOKUP(Dulieu!$C$22&"_PRE_M",Dulieu!$C$88:$N$400,4,FALSE) -> 0 | G41: =+G40-VLOOKUP(Dulieu!$C$22&"_PRE_M",Dulieu!$C$88:$N$400,5,FALSE) -> 0 | H41: =+H40-VLOOKUP(Dulieu!$C$22&"_PRE_M",Dulieu!$C$88:$N$400,6,FALSE) -> 0 | I41: =+I40-VLOOKUP(Dulieu!$C$22&"_PRE_M",Dulieu!$C$88:$N$400,7,FALSE) -> 0 | J41: =+J40-VLOOKUP(Dulieu!$C$22&"_PRE_M",Dulieu!$C$88:$N$400,8,FALSE) -> 0 | K41: =+K40-VLOOKUP(Dulieu!$C$22&"_PRE_M",Dulieu!$C$88:$N$400,9,FALSE) -> 0 | L41: =+L40-VLOOKUP(Dulieu!$C$22&"_PRE_M",Dulieu!$C$88:$N$400,10,FALSE) -> 0 | M41: =+M40-VLOOKUP(Dulieu!$C$22&"_PRE_M",Dulieu!$C$88:$N$400,11,FALSE) -> 0 | N41: =+N40-VLOOKUP(Dulieu!$C$22&"_PRE_M",Dulieu!$C$88:$N$400,12,FALSE) -> 0 | O41: =+O40-VLOOKUP(Dulieu!$C$22&"_PRE_M",Dulieu!$C$88:$Y$400,13,FALSE) -> 0 | P41: =+P40-VLOOKUP(Dulieu!$C$22&"_PRE_M",Dulieu!$C$88:$Y$400,14,FALSE) -> 0 | Q41: =+Q40-VLOOKUP(Dulieu!$C$22&"_PRE_M",Dulieu!$C$88:$Y$400,15,FALSE) -> 0 | R41: =+R40-VLOOKUP(Dulieu!$C$22&"_PRE_M",Dulieu!$C$88:$Y$400,16,FALSE) -> 0 | S41: =+S40-VLOOKUP(Dulieu!$C$22&"_PRE_M",Dulieu!$C$88:$Y$400,17,FALSE) -> 0 | T41: =+T40-VLOOKUP(Dulieu!$C$22&"_PRE_M",Dulieu!$C$88:$Y$400,18,FALSE) -> 0 | U41: =+U40-VLOOKUP(Dulieu!$C$22&"_PRE_M",Dulieu!$C$88:$Y$400,19,FALSE) -> 0 | V41: =+V40-VLOOKUP(Dulieu!$C$22&"_PRE_M",Dulieu!$C$88:$Y$400,20,FALSE) -> 0 | W41: =+W40-VLOOKUP(Dulieu!$C$22&"_PRE_M",Dulieu!$C$88:$Y$400,21,FALSE) -> 0 | X41: =+X40-VLOOKUP(Dulieu!$C$22&"_PRE_M",Dulieu!$C$88:$Y$400,22,FALSE) -> 0 | Y41: =+Y40-VLOOKUP(Dulieu!$C$22&"_PRE_M",Dulieu!$C$88:$Y$400,23,FALSE) -> 0
...

Sheet Sheet2

Sheet Sheet3
